Workbook

Sheet รับรายงานตัว
A1: รายชื่อผู้เข้ารับการฝึกอบรม
A2: หลักสูตรการปรับพื้นฐานยุทธวิธีตำรวจระดับครูฝึก (ชั้นสัญญาบัตร) รุ่นที่ 2 ประจำปีงบประมาณ ๒๕62
A3: ระหว่างวันที่ 29 กรกฎาคม - 9 สิงหาคม 2562
A4: รับรายงานตัว วันจันทร์ที่ 29 กรกฎาคม 2562
A6: ลำดับ | B6: ยศ ชื่อ สกุล | E6: ตำแหน่ง/สังกัด | F6: หมายเลขโทรศัพท์ | G6: หมายเลขบัตรประชาชน | H6: ชื่อเล่น | I6: กรุ๊ปเลือด | J6: อายุ | K6: แก้ไขยศ-ชื่อ-สกุล-ตำแหน่งเป็น | L6: ลายมือชื่อ
A7: บช.น.
A8: 1 | B8: พ.ต.ต. | C8: ณัฐพงษ์ | D8: กลิ่นลำยงค์ | E8: สวป.สน.ดินแดง บก.น.1 | F8: 081-3542939 | L8: =B8 -> พ.ต.ต.
A9: 2 | B9: ร.ต.อ. | C9: สมชาติ | D9: มีความเจริญ | E9: รอง สวป.สน.ห้วยขวาง บก.น.1 | F9: 080-3939488 | L9: =B9 -> ร.ต.อ.
A10: 3 | B10: ร.ต.อ. | C10: สุวพิชญ์ | D10: อินทร์สิงห์ | E10: รอง สวป.สน.บางเขน บก.น.2 | F10: 087-0544766 | L10: =B10 -> ร.ต.อ.
A11: 4 | B11: ร.ต.อ. | C11: โสภณ | D11: คำเวียงจันทร์ | E11: รอง สว.ธร.สน.โคกคราม บก.น.2 | F11: 087-1111879 | L11: =B11 -> ร.ต.อ.
A12: 5 | B12: ร.ต.อ. | C12: มณฑล | D12: แดงสมิง | E12: รอง สวป.สน.มีนบุรี บก.น.3 | F12: 081-1425519 | L12: =B12 -> ร.ต.อ.
A13: 6 | B13: ร.ต.อ. | C13: ณภัทรพงษ์ | D13: ขันธะหัตถ์ | E13: รอง สวป.สน.ร่มเกล้า บก.น.3 | F13: 086-5133528 | L13: =B13 -> ร.ต.อ.
A14: 7 | B14: พ.ต.ท. | C14: ณรัฐช์พงศ์ | D14: อุดมศรี | E14: รอง ผกก.(ป.) สน.บึงกุ่ม บก.น.4 | F14: 095-5545955 | L14: =B14 -> พ.ต.ท.
A15: 8 | B15: ร.ต.ท. | C15: กฤษฎา | D15: ซอประเสริฐ | E15: รอง สว.(สอบสวน) สน.บางชัน บก.น.4 | F15: 094-4818578 | L15: =B15 -> ร.ต.ท.
A16: 9 | B16: ร.ต.อ. | C16: สรกฤช | D16: ชุมหล่อ | E16: รอง สวป.สน.บางนา บก.น.5 | F16: 081-8188695 | L16: =B16 -> ร.ต.อ.
A17: 10 | B17: ร.ต.อ. | C17: กฤษณ | D17: บัวหอม | E17: รอง สวป.สน.ทุ่งมหาเมฆ | F17: 085-1273333 | L17: =B17 -> ร.ต.อ.
A18: ภ.2
A19: 11 | B19: ร.ต.ท. | C19: จักรพันธุ์ | D19: พันธุ์มณี | E19: รอง สว.กก.สืบสวน ภ.จว.จันทบุรี | F19: 092-6022062 | L19: =B19 -> ร.ต.ท.
A20: 12 | B20: ร.ต.อ. | C20: ดุสิต | D20: โชติสกุลแสงทอง | E20: รอง สวป.สภ.สอยดาว จว.ชลบุรี | F20: 089-9229687 | L20: =B20 -> ร.ต.อ.
A21: 13 | B21: ร.ต.อ. | C21: ไกรศักดิ์ | D21: เฉยฉิว | E21: รอง สว.จร.สภ.บางน้ำเปรี้ยว จว.ฉะเชิงเทรา | F21: 083-1995510 | L21: =B21 -> ร.ต.อ.
A22: 14 | B22: ร.ต.อ. | C22: ประยงค์ | D22: อยู่สาโก | E22: รอง สวป.สภ.แปลงยาว จว.ฉะเชิงเทรา | F22: 086-8231669 | L22: =B22 -> ร.ต.อ.
A23: 15 | B23: ร.ต.อ. | C23: วุฒิพงษ์ | D23: กาสา | E23: รอง สว.กก.สืบสวน ภ.จว.ชลบุรี | F23: 081-8662466 | L23: =B23 -> ร.ต.อ.
A24: 16 | B24: ร.ต.อ. | C24: ยงยุทธ | D24: กองทอง | E24: รอง สวป.สภ.ห้วยใหญ่ ภ.จว.ชลบุรี | F24: 081-1424369 | L24: =B24 -> ร.ต.อ.
A25: 17 | B25: พ.ต.ท. | C25: อาทิตย์ | D25: ธรรมสุนา | E25: สวป.สภ.วังตะเคียน จว.ปราจีนบุรี | F25: 090-9687460 | L25: =B25 -> พ.ต.ท.
A26: 18 | B26: ร.ต.อ. | C26: อนวัช | D26: พรมปะ | E26: รอง สวป.สภ.ศรีมหาโพธิ จว.ปราจีนบุรี | F26: 063-1969269 | L26: =B26 -> ร.ต.อ.
A27: 19 | B27: ร.ต.อ. | C27: สิทธา | D27: ช่อเกตุ | E27: รอง สวป.สภ.มาบตาพุด จว.ระยอง | F27: 095-7475356 | L27: =B27 -> ร.ต.อ.
A28: 20 | B28: ร.ต.อ. | C28: คมเดช | D28: ศรียางนอก | E28: รอง สวป.สภ.บ้านฉาง จว.ระยอง | F28: 081-8629339 | L28: =B28 -> ร.ต.อ.
A29: ภ.4
A30: 21 | B30: พ.ต.ท. | C30: ชวลิต | D30: อาจหาญ | E30: สวป.สภ.เกษตรวิสัย ภ.จว.ร้อยเอ็ด | F30: 08 1407 7129 | L30: =B30 -> พ.ต.ท.
A31: 22 | B31: พ.ต.ต. | C31: เนติวุธ | D31: สุดหนองบัว | E31: สวป.สภ.เมืองสรวง ภ.จว.ร้อยเอ็ด | F31: 08 9277 7045 | L31: =B31 -> พ.ต.ต.
A32: 23 | B32: ร.ต.อ. | C32: สะไกร | D32: ปิดสายะ | E32: รอง สวป.สภ.ท่าคันโท ภ.จว.กาฬสินธุ์ | F32: 09 2563 5670 | L32: =B32 -> ร.ต.อ.
A33: 24 | B33: ร.ต.อ. | C33: ปิยพล | D33: อนันต์เอื้อ | E33: รอง สว.สส.สภ.ดอนจาน ภ.จว.กาฬสินธุ์ | F33: 09 1861 7604 | L33: =B33 -> ร.ต.อ.
A34: 25 | B34: ร.ต.อ. | C34: ศิริชัย | D34: ปลัดขวา | E34: รอง สวป.ฯ ปรก.สภ.บ้านไผ่ ภ.จว.ขอนแก่น | F34: 09 8986 7996 | L34: =B34 -> ร.ต.อ.
A35: 26 | B35: ร.ต.อ. | C35: สุวสันต์ | D35: นาหาร | E35: รอง สวป.สภ.บ้านแฮด ภ.จว.ขอนแก่น | F35: 09 8584 0030 | L35: =B35 -> ร.ต.อ.
A36: 27 | B36: ร.ต.อ. | C36: ศุภชาติ | D36: โพธิจันทร์ | E36: รอง สว.กก.สืบสวน ภ.จว.หนองคาย | F36: 06 2993 5696 | L36: =B36 -> ร.ต.อ.
A37: 28 | B37: ร.ต.อ. | C37: จักริน | D37: โสดาวิชิต | E37: รอง สวป.สภ.รัตนะวาปี ภ.จว.หนองคาย | F37: 09 8492 8076 | L37: =B37 -> ร.ต.อ.
A38: 29 | B38: ร.ต.อ. | C38: ธนากร | D38: ภูขาว | E38: รอง สวป.สภ.กุมภวาปี ปรก.สภ.เมืองอุดรธานี | F38: 08 1391 5753 | L38: =B38 -> ร.ต.อ.
A39: 30 | B39: ร.ต.อ. | C39: วงศ์วริศ | D39: ธรรมโกลัง | E39: รอง สวป.สภ.นายูง ปรก.สภ.เมืองอุดรธานี | F39: 093-5195035 | L39: =B39 -> ร.ต.อ.
A40: ภ.6
A41: 31 | B41: พ.ต.ท. | C41: รุ่ง | D41: เทียนอยู่ | E41: สวป.สภ.คลองขลุง ภ.จว.กำแพงเพชร | F41: 065-2198844 | L41: =B41 -> พ.ต.ท.
...

Sheet รายชื่อ1
A1: รายชื่อผู้เข้ารับการฝึกอบรม
A2: หลักสูตรการปรับพื้นฐานยุทธวิธีตำรวจระดับครูฝึก (ชั้นสัญญาบัตร) รุ่นที่ 2 ประจำปีงบประมาณ ๒๕62
A3: ระหว่างวันที่ 29 กรกฎาคม - 9 สิงหาคม 2562
A4: ลำดับ | B4: ยศ ชื่อ สกุล | E4: ตำแหน่ง/สังกัด | F4: หมายเลขโทรศัพท์ | G4: หมายเหตุ
A5: บช.น.
A6: 1 | B6: พ.ต.ต. | C6: ณัฐพงษ์ | D6: กลิ่นลำยงค์ | E6: สวป.สน.ดินแดง บก.น.1 | F6: 081-3542939 | I6: พ.ต.ต.ณัฐพงษ์ กลิ่นลำยงค์ | J6: สวป.สน.ดินแดง บก.น.1
A7: 2 | B7: ร.ต.อ. | C7: สมชาติ | D7: มีความเจริญ | E7: รอง สวป.สน.ห้วยขวาง บก.น.1 | F7: 080-3939488 | I7: ร.ต.อ.สมชาติ มีความเจริญ | J7: รอง สวป.สน.ห้วยขวาง บก.น.1
A8: 3 | B8: ร.ต.อ. | C8: สุวพิชญ์ | D8: อินทร์สิงห์ | E8: รอง สวป.สน.บางเขน บก.น.2 | F8: 087-0544766 | I8: ร.ต.อ.สุวพิชญ์ อินทร์สิงห์ | J8: รอง สวป.สน.บางเขน บก.น.2
A9: 4 | B9: ร.ต.อ. | C9: โสภณ | D9: คำเวียงจันทร์ | E9: รอง สว.ธร.สน.โคกคราม บก.น.2 | F9: 087-1111879 | I9: ร.ต.อ.โสภณ คำเวียงจันทร์ | J9: รอง สว.ธร.สน.โคกคราม บก.น.2
A10: 5 | B10: ร.ต.อ. | C10: มณฑล | D10: แดงสมิง | E10: รอง สวป.สน.มีนบุรี บก.น.3 | F10: 081-1425519 | I10: ร.ต.อ.มณฑล แดงสมิง | J10: รอง สวป.สน.มีนบุรี บก.น.3
A11: 6 | B11: ร.ต.อ. | C11: ณภัทรพงษ์ | D11: ขันธะหัตถ์ | E11: รอง สวป.สน.ร่มเกล้า บก.น.3 | F11: 086-5133528 | I11: ร.ต.อ.ณภัทรพงษ์ ขันธะหัตถ์ | J11: รอง สวป.สน.ร่มเกล้า บก.น.3
A12: 7 | B12: พ.ต.ท. | C12: ณรัฐช์พงศ์ | D12: อุดมศรี | E12: รอง ผกก.(ป.) สน.บึงกุ่ม บก.น.4 | F12: 095-5545955 | I12: พ.ต.ท.ณรัฐช์พงศ์ อุดมศรี | J12: รอง ผกก.(ป.) สน.บึงกุ่ม บก.น.4
A13: 8 | B13: ร.ต.ท. | C13: กฤษฎา | D13: ซอประเสริฐ | E13: รอง สว.(สอบสวน) สน.บางชัน บก.น.4 | F13: 094-4818578 | I13: ร.ต.ท.กฤษฎา ซอประเสริฐ | J13: รอง สว.(สอบสวน) สน.บางชัน บก.น.4
A14: 9 | B14: ร.ต.อ. | C14: สรกฤช | D14: ชุมหล่อ | E14: รอง สวป.สน.บางนา บก.น.5 | F14: 081-8188695 | I14: ร.ต.อ.สรกฤช ชุมหล่อ | J14: รอง สวป.สน.บางนา บก.น.5
A15: 10 | B15: ร.ต.อ. | C15: กฤษณ | D15: บัวหอม | E15: รอง สวป.สน.ทุ่งมหาเมฆ | F15: 085-1273333 | I15: ร.ต.อ.กฤษณ บัวหอม | J15: รอง สวป.สน.ทุ่งมหาเมฆ
A16: ภ.2 | I16: ร.ต.ท.จักรพันธุ์ พันธุ์มณี | J16: รอง สว.กก.สืบสวน ภ.จว.จันทบุรี
A17: 11 | B17: ร.ต.ท. | C17: จักรพันธุ์ | D17: พันธุ์มณี | E17: รอง สว.กก.สืบสวน ภ.จว.จันทบุรี | F17: 092-6022062 | I17: ร.ต.อ.ดุสิต โชติสกุลแสงทอง | J17: รอง สวป.สภ.สอยดาว จว.ชลบุรี
A18: 12 | B18: ร.ต.อ. | C18: ดุสิต | D18: โชติสกุลแสงทอง | E18: รอง สวป.สภ.สอยดาว จว.ชลบุรี | F18: 089-9229687 | I18: ร.ต.อ.ไกรศักดิ์ เฉยฉิว | J18: รอง สว.จร.สภ.บางน้ำเปรี้ยว จว.ฉะเชิงเทรา
A19: 13 | B19: ร.ต.อ. | C19: ไกรศักดิ์ | D19: เฉยฉิว | E19: รอง สว.จร.สภ.บางน้ำเปรี้ยว จว.ฉะเชิงเทรา | F19: 083-1995510 | I19: ร.ต.อ.ประยงค์ อยู่สาโก | J19: รอง สวป.สภ.แปลงยาว จว.ฉะเชิงเทรา
A20: 14 | B20: ร.ต.อ. | C20: ประยงค์ | D20: อยู่สาโก | E20: รอง สวป.สภ.แปลงยาว จว.ฉะเชิงเทรา | F20: 086-8231669 | I20: ร.ต.อ.วุฒิพงษ์ กาสา | J20: รอง สว.กก.สืบสวน ภ.จว.ชลบุรี
A21: 15 | B21: ร.ต.อ. | C21: วุฒิพงษ์ | D21: กาสา | E21: รอง สว.กก.สืบสวน ภ.จว.ชลบุรี | F21: 081-8662466 | I21: ร.ต.อ.ยงยุทธ กองทอง | J21: รอง สวป.สภ.ห้วยใหญ่ ภ.จว.ชลบุรี
A22: 16 | B22: ร.ต.อ. | C22: ยงยุทธ | D22: กองทอง | E22: รอง สวป.สภ.ห้วยใหญ่ ภ.จว.ชลบุรี | F22: 081-1424369 | I22: พ.ต.ท.อาทิตย์ ธรรมสุนา | J22: สวป.สภ.วังตะเคียน จว.ปราจีนบุรี
A23: 17 | B23: พ.ต.ท. | C23: อาทิตย์ | D23: ธรรมสุนา | E23: สวป.สภ.วังตะเคียน จว.ปราจีนบุรี | F23: 090-9687460 | I23: ร.ต.อ.อนวัช พรมปะ | J23: รอง สวป.สภ.ศรีมหาโพธิ จว.ปราจีนบุรี
A24: 18 | B24: ร.ต.อ. | C24: อนวัช | D24: พรมปะ | E24: รอง สวป.สภ.ศรีมหาโพธิ จว.ปราจีนบุรี | F24: 063-1969269 | I24: ร.ต.อ.สิทธา ช่อเกตุ | J24: รอง สวป.สภ.มาบตาพุด จว.ระยอง
A25: 19 | B25: ร.ต.อ. | C25: สิทธา | D25: ช่อเกตุ | E25: รอง สวป.สภ.มาบตาพุด จว.ระยอง | F25: 095-7475356 | I25: ร.ต.อ.คมเดช ศรียางนอก | J25: รอง สวป.สภ.บ้านฉาง จว.ระยอง
A26: 20 | B26: ร.ต.อ. | C26: คมเดช | D26: ศรียางนอก | E26: รอง สวป.สภ.บ้านฉาง จว.ระยอง | F26: 081-8629339 | I26: พ.ต.ท.ชวลิต อาจหาญ | J26: สวป.สภ.เกษตรวิสัย ภ.จว.ร้อยเอ็ด
A27: ภ.4 | I27: พ.ต.ต.เนติวุธ สุดหนองบัว | J27: สวป.สภ.เมืองสรวง ภ.จว.ร้อยเอ็ด
A28: 21 | B28: พ.ต.ท. | C28: ชวลิต | D28: อาจหาญ | E28: สวป.สภ.เกษตรวิสัย ภ.จว.ร้อยเอ็ด | F28: 08 1407 7129 | I28: ร.ต.อ.สะไกร ปิดสายะ | J28: รอง สวป.สภ.ท่าคันโท ภ.จว.กาฬสินธุ์
A29: 22 | B29: พ.ต.ต. | C29: เนติวุธ | D29: สุดหนองบัว | E29: สวป.สภ.เมืองสรวง ภ.จว.ร้อยเอ็ด | F29: 08 9277 7045 | I29: ร.ต.อ.ปิยพล อนันต์เอื้อ | J29: รอง สว.สส.สภ.ดอนจาน ภ.จว.กาฬสินธุ์
A30: 23 | B30: ร.ต.อ. | C30: สะไกร | D30: ปิดสายะ | E30: รอง สวป.สภ.ท่าคันโท ภ.จว.กาฬสินธุ์ | F30: 09 2563 5670 | I30: ร.ต.อ.ศิริชัย ปลัดขวา | J30: รอง สวป.ฯ ปรก.สภ.บ้านไผ่ ภ.จว.ขอนแก่น
A31: 24 | B31: ร.ต.อ. | C31: ปิยพล | D31: อนันต์เอื้อ | E31: รอง สว.สส.สภ.ดอนจาน ภ.จว.กาฬสินธุ์ | F31: 09 1861 7604 | I31: ร.ต.อ.สุวสันต์ นาหาร | J31: รอง สวป.สภ.บ้านแฮด ภ.จว.ขอนแก่น
A32: 25 | B32: ร.ต.อ. | C32: ศิริชัย | D32: ปลัดขวา | E32: รอง สวป.ฯ ปรก.สภ.บ้านไผ่ ภ.จว.ขอนแก่น | F32: 09 8986 7996 | I32: ร.ต.อ.ศุภชาติ โพธิจันทร์ | J32: รอง สว.กก.สืบสวน ภ.จว.หนองคาย
A33: 26 | B33: ร.ต.อ. | C33: สุวสันต์ | D33: นาหาร | E33: รอง สวป.สภ.บ้านแฮด ภ.จว.ขอนแก่น | F33: 09 8584 0030 | I33: ร.ต.อ.จักริน โสดาวิชิต | J33: รอง สวป.สภ.รัตนะวาปี ภ.จว.หนองคาย
A34: 27 | B34: ร.ต.อ. | C34: ศุภชาติ | D34: โพธิจันทร์ | E34: รอง สว.กก.สืบสวน ภ.จว.หนองคาย | F34: 06 2993 5696 | I34: ร.ต.อ.ธนากร ภูขาว | J34: รอง สวป.สภ.กุมภวาปี ปรก.สภ.เมืองอุดรธานี
A35: 28 | B35: ร.ต.อ. | C35: จักริน | D35: โสดาวิชิต | E35: รอง สวป.สภ.รัตนะวาปี ภ.จว.หนองคาย | F35: 09 8492 8076 | I35: ร.ต.อ.วงศ์วริศ ธรรมโกลัง | J35: รอง สวป.สภ.นายูง ปรก.สภ.เมืองอุดรธานี
A36: 29 | B36: ร.ต.อ. | C36: ธนากร | D36: ภูขาว | E36: รอง สวป.สภ.กุมภวาปี ปรก.สภ.เมืองอุดรธานี | F36: 08 1391 5753 | I36: พ.ต.ท.รุ่ง เทียนอยู่ | J36: สวป.สภ.คลองขลุง ภ.จว.กำแพงเพชร
A37: 30 | B37: ร.ต.อ. | C37: วงศ์วริศ | D37: ธรรมโกลัง | E37: รอง สวป.สภ.นายูง ปรก.สภ.เมืองอุดรธานี | F37: 093-5195035 | I37: พ.ต.ท.บุญนพ คำมูล | J37: สวป.สภ.ไทรงาม ภ.จว.กำแพงเพชร
A38: ภ.6 | I38: ร.ต.อ.วีรพงศ์ สีลินลี | J38: รอง สวป.สภ.ลาดยาว ภ.จว.นครสวรรค์
A39: 31 | B39: พ.ต.ท. | C39: รุ่ง | D39: เทียนอยู่ | E39: สวป.สภ.คลองขลุง ภ.จว.กำแพงเพชร | F39: 065-2198844 | I39: ร.ต.อ.ชาคลีรัตน์ ปาสร้อย | J39: รอง สวป.สภ.บรรพตพิสัย ภ.จว.นครสวรรค์
A40: 32 | B40: พ.ต.ท. | C40: บุญนพ | D40: คำมูล | E40: สวป.สภ.ไทรงาม ภ.จว.กำแพงเพชร | F40: 087-1985597 | I40: ร.ต.อ.อนุกุล จันทร์นุช | J40: รอง สวป.สภ.บางมูลนาก ภ.จว.พิจิตร
...

Sheet คะแนน
A1: รายชื่อผู้เข้ารับการฝึกอบรม
A2: หลักสูตรการปรับพื้นฐานยุทธวิธีตำรวจระดับครูฝึก (ชั้นสัญญาบัตร) รุ่นที่ 1 ประจำปีงบประมาณ ๒๕62
A3: ระหว่างวันที่ 29 กรกฎาคม - 9 สิงหาคม 2562
A4: ลำดับ | B4: ยศ ชื่อ สกุล | E4: ตำแหน่ง/สังกัด | F4: บันทึกคะแนน

Sheet จำหน่ายกระสุน
A1: บัญชีจ่ายกระสุน ขนาด 9 มม.
A2: หลักสูตรการปรับพื้นฐานยุทธวิธีตำรวจระดับครูฝึก (ชั้นสัญญาบัตร) รุ่นที่ 1 ประจำปีงบประมาณ ๒๕62
A3: จำนวนคนละ 150 นัด
A4: ระหว่างวันที่ 29 กรกฎาคม - 9 สิงหาคม 2562
A5: ลำดับ | B5: ยศ ชื่อ สกุล | E5: ตำแหน่ง/สังกัด | F5: จำนวนนัด | G5: ลายมือชื่อ
A6: ภ.1
A7: 1 | F7: 150 | G7: =B7 -> 0
A8: 2 | F8: 150 | G8: =B8 -> 0
A9: 3 | F9: 150 | G9: =B9 -> 0
A10: 4 | F10: 150 | G10: =B10 -> 0
A11: 5 | F11: 150 | G11: =B11 -> 0
A12: 6 | F12: 150 | G12: =B12 -> 0
A13: 7 | F13: 150 | G13: =B13 -> 0
A14: 8 | F14: 150 | G14: =B14 -> 0
A15: 9 | F15: 150 | G15: =B15 -> 0
A16: 10 | F16: 150 | G16: =B16 -> 0
A17: ภ.3
A18: 11 | F18: 150 | G18: =B18 -> 0
A19: 12 | F19: 150 | G19: =B19 -> 0
A20: 13 | F20: 150 | G20: =B20 -> 0
A21: 14 | F21: 150 | G21: =B21 -> 0
A22: 15 | F22: 150 | G22: =B22 -> 0
A23: 16 | F23: 150 | G23: =B23 -> 0
A24: 17 | F24: 150 | G24: =B24 -> 0
A25: 18 | F25: 150 | G25: =B25 -> 0
A26: 19 | F26: 150 | G26: =B26 -> 0
A27: 20 | F27: 150 | G27: =B27 -> 0
A28: ภ.5
A29: 21 | F29: 150 | G29: =B29 -> 0
A30: 22 | F30: 150 | G30: =B30 -> 0
A31: 23 | F31: 150 | G31: =B31 -> 0
A32: 24 | F32: 150 | G32: =B32 -> 0
A33: 25 | F33: 150 | G33: =B33 -> 0
A34: 26 | F34: 150 | G34: =B34 -> 0
A35: 27 | F35: 150 | G35: =B35 -> 0
A36: 28 | F36: 150 | G36: =B36 -> 0
A37: 29 | F37: 150 | G37: =B37 -> 0
A38: 30 | F38: 150 | G38: =B38 -> 0
A39: ภ.7
A40: 31 | F40: 150 | G40: =B40 -> 0
...

Sheet เช็คชื่อ
A1: หลักสูตรการปรับพื้นฐานยุทธวิธีตำรวจระดับครูฝึก (ชั้นสัญญาบัตร) รุ่นที่ 2 ประจำปีงบประมาณ ๒๕62
A2: ลำดับ | B2: ยศ ชื่อ สกุล | C2: 43675 | D2: 43676 | E2: 43677 | F2: 43678 | G2: 43679 | H2: 43682 | I2: 43683 | J2: 43684 | K2: 43685 | L2: 43686
A3: 1 | B3: พ.ต.ต.ณัฐพงษ์ กลิ่นลำยงค์
A4: 2 | B4: ร.ต.อ.สมชาติ มีความเจริญ
A5: 3 | B5: ร.ต.อ.สุวพิชญ์ อินทร์สิงห์
A6: 4 | B6: ร.ต.อ.โสภณ คำเวียงจันทร์
A7: 5 | B7: ร.ต.อ.มณฑล แดงสมิง
A8: 6 | B8: ร.ต.อ.ณภัทรพงษ์ ขันธะหัตถ์
A9: 7 | B9: พ.ต.ท.ณรัฐช์พงศ์ อุดมศรี
A10: 8 | B10: ร.ต.ท.กฤษฎา ซอประเสริฐ
A11: 9 | B11: ร.ต.อ.สรกฤช ชุมหล่อ
A12: 10 | B12: ร.ต.อ.กฤษณ บัวหอม
A13: 11 | B13: ร.ต.ท.จักรพันธุ์ พันธุ์มณี
A14: 12 | B14: ร.ต.อ.ดุสิต โชติสกุลแสงทอง
... A52: 50 | B52: ร.ต.อ.ธัชพล มณีแสง

Sheet เข้าเรียน
A1: หลักสูตรการปรับพื้นฐานยุทธวิธีตำรวจระดับครูฝึก (ชั้นสัญญาบัตร) รุ่นที่ 2 ประจำปีงบประมาณ ๒๕62
A2: ระหว่างวันที่ 29 กรกฎาคม - 9 สิงหาคม 2562
A3: วันที่ 2 สิงหาคม 2562
A5: ลำดับ | B5: ยศ ชื่อ สกุล | E5: ตำแหน่ง/สังกัด | F5: ลายมือชื่อ
F6: เช้า | G6: บ่าย
A7: บช.น.
A8: 1 | B8: พ.ต.ต. | C8: ณัฐพงษ์ | D8: กลิ่นลำยงค์ | E8: สวป.สน.ดินแดง บก.น.1 | F8: =B8 -> พ.ต.ต. | G8: =B8 -> พ.ต.ต.
A9: 2 | B9: ร.ต.อ. | C9: สมชาติ | D9: มีความเจริญ | E9: รอง สวป.สน.ห้วยขวาง บก.น.1 | F9: =B9 -> ร.ต.อ. | G9: =B9 -> ร.ต.อ.
A10: 3 | B10: ร.ต.อ. | C10: สุวพิชญ์ | D10: อินทร์สิงห์ | E10: รอง สวป.สน.บางเขน บก.น.2 | F10: =B10 -> ร.ต.อ. | G10: =B10 -> ร.ต.อ.
A11: 4 | B11: ร.ต.อ. | C11: โสภณ | D11: คำเวียงจันทร์ | E11: รอง สว.ธร.สน.โคกคราม บก.น.2 | F11: =B11 -> ร.ต.อ. | G11: =B11 -> ร.ต.อ.
A12: 5 | B12: ร.ต.อ. | C12: มณฑล | D12: แดงสมิง | E12: รอง สวป.สน.มีนบุรี บก.น.3 | F12: =B12 -> ร.ต.อ. | G12: =B12 -> ร.ต.อ.
A13: 6 | B13: ร.ต.อ. | C13: ณภัทรพงษ์ | D13: ขันธะหัตถ์ | E13: รอง สวป.สน.ร่มเกล้า บก.น.3 | F13: =B13 -> ร.ต.อ. | G13: =B13 -> ร.ต.อ.
A14: 7 | B14: พ.ต.ท. | C14: ณรัฐช์พงศ์ | D14: อุดมศรี | E14: รอง ผกก.(ป.) สน.บึงกุ่ม บก.น.4 | F14: =B14 -> พ.ต.ท. | G14: =B14 -> พ.ต.ท.
A15: 8 | B15: ร.ต.ท. | C15: กฤษฎา | D15: ซอประเสริฐ | E15: รอง สว.(สอบสวน) สน.บางชัน บก.น.4 | F15: =B15 -> ร.ต.ท. | G15: =B15 -> ร.ต.ท.
A16: 9 | B16: ร.ต.อ. | C16: สรกฤช | D16: ชุมหล่อ | E16: รอง สวป.สน.บางนา บก.น.5 | F16: =B16 -> ร.ต.อ. | G16: =B16 -> ร.ต.อ.
A17: 10 | B17: ร.ต.อ. | C17: กฤษณ | D17: บัวหอม | E17: รอง สวป.สน.ทุ่งมหาเมฆ | F17: =B17 -> ร.ต.อ. | G17: =B17 -> ร.ต.อ.
A18: ภ.2
A19: 11 | B19: ร.ต.ท. | C19: จักรพันธุ์ | D19: พันธุ์มณี | E19: รอง สว.กก.สืบสวน ภ.จว.จันทบุรี | F19: =B19 -> ร.ต.ท. | G19: =B19 -> ร.ต.ท.
A20: 12 | B20: ร.ต.อ. | C20: ดุสิต | D20: โชติสกุลแสงทอง | E20: รอง สวป.สภ.สอยดาว จว.ชลบุรี | F20: =B20 -> ร.ต.อ. | G20: =B20 -> ร.ต.อ.
A21: 13 | B21: ร.ต.อ. | C21: ไกรศักดิ์ | D21: เฉยฉิว | E21: รอง สว.จร.สภ.บางน้ำเปรี้ยว จว.ฉะเชิงเทรา | F21: =B21 -> ร.ต.อ. | G21: =B21 -> ร.ต.อ.
A22: 14 | B22: ร.ต.อ. | C22: ประยงค์ | D22: อยู่สาโก | E22: รอง สวป.สภ.แปลงยาว จว.ฉะเชิงเทรา | F22: =B22 -> ร.ต.อ. | G22: =B22 -> ร.ต.อ.
A23: 15 | B23: ร.ต.อ. | C23: วุฒิพงษ์ | D23: กาสา | E23: รอง สว.กก.สืบสวน ภ.จว.ชลบุรี | F23: =B23 -> ร.ต.อ. | G23: =B23 -> ร.ต.อ.
A24: 16 | B24: ร.ต.อ. | C24: ยงยุทธ | D24: กองทอง | E24: รอง สวป.สภ.ห้วยใหญ่ ภ.จว.ชลบุรี | F24: =B24 -> ร.ต.อ. | G24: =B24 -> ร.ต.อ.
A25: 17 | B25: พ.ต.ท. | C25: อาทิตย์ | D25: ธรรมสุนา | E25: สวป.สภ.วังตะเคียน จว.ปราจีนบุรี | F25: =B25 -> พ.ต.ท. | G25: =B25 -> พ.ต.ท.
A26: 18 | B26: ร.ต.อ. | C26: อนวัช | D26: พรมปะ | E26: รอง สวป.สภ.ศรีมหาโพธิ จว.ปราจีนบุรี | F26: =B26 -> ร.ต.อ. | G26: =B26 -> ร.ต.อ.
A27: 19 | B27: ร.ต.อ. | C27: สิทธา | D27: ช่อเกตุ | E27: รอง สวป.สภ.มาบตาพุด จว.ระยอง | F27: =B27 -> ร.ต.อ. | G27: =B27 -> ร.ต.อ.
A28: 20 | B28: ร.ต.อ. | C28: คมเดช | D28: ศรียางนอก | E28: รอง สวป.สภ.บ้านฉาง จว.ระยอง | F28: =B28 -> ร.ต.อ. | G28: =B28 -> ร.ต.อ.
A29: ภ.4
A30: 21 | B30: พ.ต.ท. | C30: ชวลิต | D30: อาจหาญ | E30: สวป.สภ.เกษตรวิสัย ภ.จว.ร้อยเอ็ด | F30: =B30 -> พ.ต.ท. | G30: =B30 -> พ.ต.ท.
A31: 22 | B31: พ.ต.ต. | C31: เนติวุธ | D31: สุดหนองบัว | E31: สวป.สภ.เมืองสรวง ภ.จว.ร้อยเอ็ด | F31: =B31 -> พ.ต.ต. | G31: =B31 -> พ.ต.ต.
A32: 23 | B32: ร.ต.อ. | C32: สะไกร | D32: ปิดสายะ | E32: รอง สวป.สภ.ท่าคันโท ภ.จว.กาฬสินธุ์ | F32: =B32 -> ร.ต.อ. | G32: =B32 -> ร.ต.อ.
A33: 24 | B33: ร.ต.อ. | C33: ปิยพล | D33: อนันต์เอื้อ | E33: รอง สว.สส.สภ.ดอนจาน ภ.จว.กาฬสินธุ์ | F33: =B33 -> ร.ต.อ. | G33: =B33 -> ร.ต.อ.
A34: 25 | B34: ร.ต.อ. | C34: ศิริชัย | D34: ปลัดขวา | E34: รอง สวป.ฯ ปรก.สภ.บ้านไผ่ ภ.จว.ขอนแก่น | F34: =B34 -> ร.ต.อ. | G34: =B34 -> ร.ต.อ.
A35: 26 | B35: ร.ต.อ. | C35: สุวสันต์ | D35: นาหาร | E35: รอง สวป.สภ.บ้านแฮด ภ.จว.ขอนแก่น | F35: =B35 -> ร.ต.อ. | G35: =B35 -> ร.ต.อ.
A36: 27 | B36: ร.ต.อ. | C36: ศุภชาติ | D36: โพธิจันทร์ | E36: รอง สว.กก.สืบสวน ภ.จว.หนองคาย | F36: =B36 -> ร.ต.อ. | G36: =B36 -> ร.ต.อ.
A37: 28 | B37: ร.ต.อ. | C37: จักริน | D37: โสดาวิชิต | E37: รอง สวป.สภ.รัตนะวาปี ภ.จว.หนองคาย | F37: =B37 -> ร.ต.อ. | G37: =B37 -> ร.ต.อ.
A38: 29 | B38: ร.ต.อ. | C38: ธนากร | D38: ภูขาว | E38: รอง สวป.สภ.กุมภวาปี ปรก.สภ.เมืองอุดรธานี | F38: =B38 -> ร.ต.อ. | G38: =B38 -> ร.ต.อ.
A39: 30 | B39: ร.ต.อ. | C39: วงศ์วริศ | D39: ธรรมโกลัง | E39: รอง สวป.สภ.นายูง ปรก.สภ.เมืองอุดรธานี | F39: =B39 -> ร.ต.อ. | G39: =B39 -> ร.ต.อ.
A40: ภ.6
A41: 31 | B41: พ.ต.ท. | C41: รุ่ง | D41: เทียนอยู่ | E41: สวป.สภ.คลองขลุง ภ.จว.กำแพงเพชร | F41: =B41 -> พ.ต.ท. | G41: =B41 -> พ.ต.ท.
...

Sheet ค่าอาหาร
A1: รายชื่อผู้เข้ารับการฝึกอบรม
A2: หลักสูตรการปรับพื้นฐานยุทธวิธีตำรวจระดับครูฝึก (ชั้นสัญญาบัตร) รุ่นที่ 2 ประจำปีงบประมาณ ๒๕62
A3: ประกอบการเบิกค่าใช้จ่ายฝึกอบรม (อาหาร,อาหารว่างและเครื่องดื่ม)
A4: ระหว่างวันที่ 29 กรกฎาคม - 9 สิงหาคม 2562
A6: ลำดับ | B6: ยศ ชื่อ สกุล | E6: ตำแหน่ง/สังกัด | F6: ลายมือชื่อ
A7: บช.น.
A8: 1 | B8: พ.ต.ต. | C8: ณัฐพงษ์ | D8: กลิ่นลำยงค์ | E8: สวป.สน.ดินแดง บก.น.1 | F8: =B8 -> พ.ต.ต.
A9: 2 | B9: ร.ต.อ. | C9: สมชาติ | D9: มีความเจริญ | E9: รอง สวป.สน.ห้วยขวาง บก.น.1 | F9: =B9 -> ร.ต.อ.
A10: 3 | B10: ร.ต.อ. | C10: สุวพิชญ์ | D10: อินทร์สิงห์ | E10: รอง สวป.สน.บางเขน บก.น.2 | F10: =B10 -> ร.ต.อ.
A11: 4 | B11: ร.ต.อ. | C11: โสภณ | D11: คำเวียงจันทร์ | E11: รอง สว.ธร.สน.โคกคราม บก.น.2 | F11: =B11 -> ร.ต.อ.
A12: 5 | B12: ร.ต.อ. | C12: มณฑล | D12: แดงสมิง | E12: รอง สวป.สน.มีนบุรี บก.น.3 | F12: =B12 -> ร.ต.อ.
A13: 6 | B13: ร.ต.อ. | C13: ณภัทรพงษ์ | D13: ขันธะหัตถ์ | E13: รอง สวป.สน.ร่มเกล้า บก.น.3 | F13: =B13 -> ร.ต.อ.
A14: 7 | B14: พ.ต.ท. | C14: ณรัฐช์พงศ์ | D14: อุดมศรี | E14: รอง ผกก.(ป.) สน.บึงกุ่ม บก.น.4 | F14: =B14 -> พ.ต.ท.
A15: 8 | B15: ร.ต.ท. | C15: กฤษฎา | D15: ซอประเสริฐ | E15: รอง สว.(สอบสวน) สน.บางชัน บก.น.4 | F15: =B15 -> ร.ต.ท.
A16: 9 | B16: ร.ต.อ. | C16: สรกฤช | D16: ชุมหล่อ | E16: รอง สวป.สน.บางนา บก.น.5 | F16: =B16 -> ร.ต.อ.
A17: 10 | B17: ร.ต.อ. | C17: กฤษณ | D17: บัวหอม | E17: รอง สวป.สน.ทุ่งมหาเมฆ | F17: =B17 -> ร.ต.อ.
A18: ภ.2
A19: 11 | B19: ร.ต.ท. | C19: จักรพันธุ์ | D19: พันธุ์มณี | E19: รอง สว.กก.สืบสวน ภ.จว.จันทบุรี | F19: =B19 -> ร.ต.ท.
A20: 12 | B20: ร.ต.อ. | C20: ดุสิต | D20: โชติสกุลแสงทอง | E20: รอง สวป.สภ.สอยดาว จว.ชลบุรี | F20: =B20 -> ร.ต.อ.
A21: 13 | B21: ร.ต.อ. | C21: ไกรศักดิ์ | D21: เฉยฉิว | E21: รอง สว.จร.สภ.บางน้ำเปรี้ยว จว.ฉะเชิงเทรา | F21: =B21 -> ร.ต.อ.
A22: 14 | B22: ร.ต.อ. | C22: ประยงค์ | D22: อยู่สาโก | E22: รอง สวป.สภ.แปลงยาว จว.ฉะเชิงเทรา | F22: =B22 -> ร.ต.อ.
A23: 15 | B23: ร.ต.อ. | C23: วุฒิพงษ์ | D23: กาสา | E23: รอง สว.กก.สืบสวน ภ.จว.ชลบุรี | F23: =B23 -> ร.ต.อ.
A24: 16 | B24: ร.ต.อ. | C24: ยงยุทธ | D24: กองทอง | E24: รอง สวป.สภ.ห้วยใหญ่ ภ.จว.ชลบุรี | F24: =B24 -> ร.ต.อ.
A25: 17 | B25: พ.ต.ท. | C25: อาทิตย์ | D25: ธรรมสุนา | E25: สวป.สภ.วังตะเคียน จว.ปราจีนบุรี | F25: =B25 -> พ.ต.ท.
A26: 18 | B26: ร.ต.อ. | C26: อนวัช | D26: พรมปะ | E26: รอง สวป.สภ.ศรีมหาโพธิ จว.ปราจีนบุรี | F26: =B26 -> ร.ต.อ.
A27: 19 | B27: ร.ต.อ. | C27: สิทธา | D27: ช่อเกตุ | E27: รอง สวป.สภ.มาบตาพุด จว.ระยอง | F27: =B27 -> ร.ต.อ.
A28: 20 | B28: ร.ต.อ. | C28: คมเดช | D28: ศรียางนอก | E28: รอง สวป.สภ.บ้านฉาง จว.ระยอง | F28: =B28 -> ร.ต.อ.
A29: ภ.4
A30: 21 | B30: พ.ต.ท. | C30: ชวลิต | D30: อาจหาญ | E30: สวป.สภ.เกษตรวิสัย ภ.จว.ร้อยเอ็ด | F30: =B30 -> พ.ต.ท.
A31: 22 | B31: พ.ต.ต. | C31: เนติวุธ | D31: สุดหนองบัว | E31: สวป.สภ.เมืองสรวง ภ.จว.ร้อยเอ็ด | F31: =B31 -> พ.ต.ต.
A32: 23 | B32: ร.ต.อ. | C32: สะไกร | D32: ปิดสายะ | E32: รอง สวป.สภ.ท่าคันโท ภ.จว.กาฬสินธุ์ | F32: =B32 -> ร.ต.อ.
A33: 24 | B33: ร.ต.อ. | C33: ปิยพล | D33: อนันต์เอื้อ | E33: รอง สว.สส.สภ.ดอนจาน ภ.จว.กาฬสินธุ์ | F33: =B33 -> ร.ต.อ.
A34: 25 | B34: ร.ต.อ. | C34: ศิริชัย | D34: ปลัดขวา | E34: รอง สวป.ฯ ปรก.สภ.บ้านไผ่ ภ.จว.ขอนแก่น | F34: =B34 -> ร.ต.อ.
A35: 26 | B35: ร.ต.อ. | C35: สุวสันต์ | D35: นาหาร | E35: รอง สวป.สภ.บ้านแฮด ภ.จว.ขอนแก่น | F35: =B35 -> ร.ต.อ.
A36: 27 | B36: ร.ต.อ. | C36: ศุภชาติ | D36: โพธิจันทร์ | E36: รอง สว.กก.สืบสวน ภ.จว.หนองคาย | F36: =B36 -> ร.ต.อ.
A37: 28 | B37: ร.ต.อ. | C37: จักริน | D37: โสดาวิชิต | E37: รอง สวป.สภ.รัตนะวาปี ภ.จว.หนองคาย | F37: =B37 -> ร.ต.อ.
A38: 29 | B38: ร.ต.อ. | C38: ธนากร | D38: ภูขาว | E38: รอง สวป.สภ.กุมภวาปี ปรก.สภ.เมืองอุดรธานี | F38: =B38 -> ร.ต.อ.
A39: 30 | B39: ร.ต.อ. | C39: วงศ์วริศ | D39: ธรรมโกลัง | E39: รอง สวป.สภ.นายูง ปรก.สภ.เมืองอุดรธานี | F39: =B39 -> ร.ต.อ.
A40: ภ.6
A41: 31 | B41: พ.ต.ท. | C41: รุ่ง | D41: เทียนอยู่ | E41: สวป.สภ.คลองขลุง ภ.จว.กำแพงเพชร | F41: =B41 -> พ.ต.ท.
...

Sheet ตรวจสอบชื่อพิมพ์ประกาศ
A1: หลักสูตรการปรับพื้นฐานยุทธวิธีตำรวจระดับครูฝึก (ชั้นสัญญาบัตร) รุ่นที่ 2 ประจำปีงบประมาณ ๒๕62
A2: ระหว่างวันที่ 20 - 31 พฤษภาคม 2562
A3: โปรดตรวจสอบแก้ไข ยศ ชื่อ สกุล ตำแหน่ง เพื่อจัดทำวุฒิบัตร
A5: ลำดับ | B5: ยศ ชื่อ สกุล | C5: **ถ้าผิด แก้ไขเป็น** | D5: ลายมือชื่อ
A6: 1 | B6: พันตำรวจตรี ณัฐพงษ์ กลิ่นลำยงค์ | D6: =รับรายงานตัว!B8 -> พ.ต.ต.
A7: 2 | B7: ร้อยตำรวจเอก สมชาติ มีความเจริญ | D7: =รับรายงานตัว!B9 -> ร.ต.อ.
A8: 3 | B8: ร้อยตำรวจเอก สุวพิชญ์ อินทร์สิงห์ | D8: =รับรายงานตัว!B10 -> ร.ต.อ.
A9: 4 | B9: ร้อยตำรวจเอก โสภณ คำเวียงจันทร์ | D9: =รับรายงานตัว!B11 -> ร.ต.อ.
A10: 5 | B10: ร้อยตำรวจเอก มณฑล แดงสมิง | D10: =รับรายงานตัว!B12 -> ร.ต.อ.
A11: 6 | B11: ร้อยตำรวจเอก ณภัทรพงษ์ ขันธะหัตถ์ | D11: =รับรายงานตัว!B13 -> ร.ต.อ.
A12: 7 | B12: พันตำรวจโท ณรัฐช์พงศ์ อุดมศรี | D12: =รับรายงานตัว!B14 -> พ.ต.ท.
A13: 8 | B13: ร้อยตำรวจโท กฤษฎา ซอประเสริฐ | D13: =รับรายงานตัว!B15 -> ร.ต.ท.
A14: 9 | B14: ร้อยตำรวจเอก สรกฤช ชุมหล่อ | D14: =รับรายงานตัว!B16 -> ร.ต.อ.
A15: 10 | B15: ร้อยตำรวจเอก กฤษณ บัวหอม | D15: =รับรายงานตัว!B17 -> ร.ต.อ.
A16: 11 | B16: ร้อยตำรวจโท จักรพันธุ์ พันธุ์มณี | D16: =รับรายงานตัว!B19 -> ร.ต.ท.
A17: 12 | B17: ร้อยตำรวจเอก ดุสิต โชติสกุลแสงทอง | D17: =รับรายงานตัว!B20 -> ร.ต.อ.
A18: 13 | B18: ร้อยตำรวจเอก ไกรศักดิ์ เฉยฉิว | D18: =รับรายงานตัว!B21 -> ร.ต.อ.
A19: 14 | B19: ร้อยตำรวจเอก ประยงค์ อยู่สาโก | D19: =รับรายงานตัว!B22 -> ร.ต.อ.
A20: 15 | B20: ร้อยตำรวจเอก วุฒิพงษ์ กาสา | D20: =รับรายงานตัว!B23 -> ร.ต.อ.
A21: 16 | B21: ร้อยตำรวจเอก ยงยุทธ กองทอง | D21: =รับรายงานตัว!B24 -> ร.ต.อ.
A22: 17 | B22: พันตำรวจโท อาทิตย์ ธรรมสุนา | D22: =รับรายงานตัว!B25 -> พ.ต.ท.
A23: 18 | B23: ร้อยตำรวจเอก อนวัช พรมปะ | D23: =รับรายงานตัว!B26 -> ร.ต.อ.
A24: 19 | B24: ร้อยตำรวจเอก สิทธา ช่อเกตุ | D24: =รับรายงานตัว!B27 -> ร.ต.อ.
A25: 20 | B25: ร้อยตำรวจเอก คมเดช ศรียางนอก | D25: =รับรายงานตัว!B28 -> ร.ต.อ.
A26: 21 | B26: พันตำรวจโท ชวลิต อาจหาญ | D26: =รับรายงานตัว!B30 -> พ.ต.ท.
A27: 22 | B27: พันตำรวจตรี เนติวุธ สุดหนองบัว | D27: =รับรายงานตัว!B31 -> พ.ต.ต.
A28: 23 | B28: ร้อยตำรวจเอก สะไกร ปิดสายะ | D28: =รับรายงานตัว!B32 -> ร.ต.อ.
A29: 24 | B29: ร้อยตำรวจเอก ปิยพล อนันต์เอื้อ | D29: =รับรายงานตัว!B33 -> ร.ต.อ.
A30: 25 | B30: ร้อยตำรวจเอก ศิริชัย ปลัดขวา | D30: =รับรายงานตัว!B34 -> ร.ต.อ.
A31: 26 | B31: ร้อยตำรวจเอก สุวสันต์ นาหาร | D31: =รับรายงานตัว!B35 -> ร.ต.อ.
A32: 27 | B32: ร้อยตำรวจเอก ศุภชาติ โพธิจันทร์ | D32: =รับรายงานตัว!B36 -> ร.ต.อ.
A33: 28 | B33: ร้อยตำรวจเอก จักริน โสดาวิชิต | D33: =รับรายงานตัว!B37 -> ร.ต.อ.
A34: 29 | B34: ร้อยตำรวจเอก ธนากร ภูขาว | D34: =รับรายงานตัว!B38 -> ร.ต.อ.
A35: 30 | B35: ร้อยตำรวจเอก วงศ์วริศ ธรรมโกลัง | D35: =รับรายงานตัว!B39 -> ร.ต.อ.
A36: 31 | B36: พันตำรวจโท รุ่ง เทียนอยู่ | D36: =รับรายงานตัว!B41 -> พ.ต.ท.
A37: 32 | B37: พันตำรวจโท บุญนพ คำมูล | D37: =รับรายงานตัว!B42 -> พ.ต.ท.
A38: 33 | B38: ร้อยตำรวจเอก วีรพงค์ สีลินลี | D38: =รับรายงานตัว!B43 -> ร.ต.อ.
A39: 34 | B39: ร้อยตำรวจเอก ชาคลีรัตน์ ปาสร้อย | D39: =รับรายงานตัว!B44 -> ร.ต.อ.
A40: 35 | B40: ร้อยตำรวจเอก อนุกูล จันทร์นุช | D40: =รับรายงานตัว!B45 -> ร.ต.อ.
A41: 36 | B41: ร้อยตำรวจเอก อุทัย รอดอยู่ | D41: =รับรายงานตัว!B46 -> ร.ต.อ.
...

Sheet Sheet1
A1: บัญชีรายชื่อผู้สำเร็จการฝึกอบรม
A2: หลักสูตรการปรับพื้นฐานยุทธวิธีตำรวจระดับครูฝึก (ชั้นสัญญาบัตร) รุ่นที่ 1
A4: ลำดับ | B4: ยศ ชื่อ สกุล
A5: 1
A6: 2
A7: 3
A8: 4
A9: 5
A10: 6
A11: 7
A12: 8
A13: 9
A14: 10
A15: 11
A16: 12
... A54: 50

Sheet ข้อมูลทำเนียบ
A1: หลักสูตรการปรับพื้นฐานยุทธวิธีตำรวจระดับครูฝึก (ชั้นสัญญาบัตร) รุ่นที่ 1 ประจำปีงบประมาณ ๒๕62
A2: โปรดกรอกข้อมูลให้ถูกต้อง ครบถ้วน
A3: ลำดับ | B3: ยศ ชื่อ สกุล | C3: ตำแหน่ง | D3: ชื่อเล่น | I3: เบอร์โทร | J3: กรุ๊ปเลือด
A4: 1 | B4: พ.ต.ต.ณัฐพงษ์ กลิ่นลำยงค์/น้อย | C4: สวป.สน.ดินแดง บก.น.1 | J4: Rh. | K4: B | L4: =J4&K4 -> Rh.B
A5: 2 | B5: ร.ต.อ.สมชาติ มีความเจริญ/ชาติ | C5: รอง สวป.สน.ห้วยขวาง บก.น.1 | J5: Rh. | K5: O | L5: =J5&K5 -> Rh.O
A6: 3 | B6: ร.ต.อ.สุวพิชญ์ อินทร์สิงห์/พิช | C6: รอง สวป.สน.บางเขน บก.น.2 | J6: Rh. | K6: O | L6: =J6&K6 -> Rh.O
A7: 4 | B7: ร.ต.อ.โสภณ คำเวียงจันทร์/ปิ๊ก | C7: รอง สว.ธร.สน.โคกคราม บก.น.2 | J7: Rh. | K7: B | L7: =J7&K7 -> Rh.B
A8: 5 | B8: ร.ต.อ.มณฑล แดงสมิง/แดง | C8: รอง สวป.สน.มีนบุรี บก.น.3 | J8: Rh. | K8: B | L8: =J8&K8 -> Rh.B
A9: 6 | B9: ร.ต.อ.ณภัทรพงษ์ ขันธะหัตถ์/พงษ์ | C9: รอง สวป.สน.ร่มเกล้า บก.น.3 | J9: Rh. | K9: B | L9: =J9&K9 -> Rh.B
A10: 7 | B10: พ.ต.ท.ณรัฐช์พงศ์ อุดมศรี/ต้อม | C10: รอง ผกก.(ป.) สน.บึงกุ่ม บก.น.4 | J10: Rh. | K10: O | L10: =J10&K10 -> Rh.O
A11: 8 | B11: ร.ต.ท.กฤษฎา ซอประเสริฐ/จี๊ | C11: รอง สว.(สอบสวน) สน.บางชัน บก.น.4 | J11: Rh. | K11: A | L11: =J11&K11 -> Rh.A
A12: 9 | B12: ร.ต.อ.สรกฤช ชุมหล่อ/พงศ์ | C12: รอง สวป.สน.บางนา บก.น.5 | J12: Rh. | K12: O | L12: =J12&K12 -> Rh.O
A13: 10 | B13: ร.ต.อ.กฤษณ บัวหอม/ตุ้ม | C13: รอง สวป.สน.ทุ่งมหาเมฆ | J13: Rh. | K13: O | L13: =J13&K13 -> Rh.O
A14: 11 | B14: ร.ต.ท.จักรพันธุ์ พันธุ์มณี /หนึ่ง | C14: รอง สว.กก.สืบสวน ภ.จว.จันทบุรี | J14: Rh. | K14: A | L14: =J14&K14 -> Rh.A
A15: 12 | B15: ร.ต.อ.ดุสิต โชติสกุลแสงทอง/ดุ | C15: รอง สวป.สภ.สอยดาว จว.ชลบุรี | J15: Rh. | K15: B | L15: =J15&K15 -> Rh.B
... A44: 41 | B44: ร.ต.อ.ไกรวุฒิ แก้วภิรมย์ | C44: รอง สวป.สภ.ปากเกร็ด ภ.จว.นนทบุรี | J44: Rh. | K44: O | L44: =J44&K44 -> Rh.O
A45: 42 | B45: ร.ต.อ.วัฒนา ศรีศิลป์/เจี๊ยบ | C45: รอง สวป.สภ.บ้านตาขุน ภ.จว.สุราษฎร์ธานี | J45: Rh. | L45: =J45&K45 -> Rh.
A46: 43 | B46: ร.ต.อ.มนตรี พรหมแก้ว/มน | C46: รอง สว.กก.สส.ภ.จว.นครศรีธรรมราช | J46: Rh. | K46: A | L46: =J46&K46 -> Rh.A
A47: 44 | B47: ร.ต.อ.หัตพัต ใจโปร่ง/เอ็ม | C47: รอง สว.กก.สส.ภ.จว.นครศรีธรรมราช | J47: Rh. | K47: O | L47: =J47&K47 -> Rh.O
A48: 45 | B48: ร.ต.อ.เศรษฐพงศ์ สุกกระ/เส | C48: รอง สวป.สภ.อ่าวนาง ภ.จว.กระบี่ | J48: Rh. | K48: O | L48: =J48&K48 -> Rh.O
A49: 46 | B49: ร.ต.อ.สัจจะ สมกำลัง/จะ | C49: รอง สว.สส.สภ.ทรายขาว ภ.จว.กระบี่ | J49: Rh. | K49: A | L49: =J49&K49 -> Rh.A
A50: 47 | B50: ร.ต.อ.สุวิศิษฏ์ คีรีรักษ์/เอก | C50: รอง สวป.สภ.ป่าตอง ภ.จว.ภูเก็ต | J50: Rh. | K50: O | L50: =J50&K50 -> Rh.O
A51: 48 | B51: ร.ต.อ.อภิเชษฐ์ คีรีเพ็ชร/เชษฐ์ | C51: รอง สวป.สภ.หลังสวน ภ.จว.ชุมพร | J51: Rh. | K51: A | L51: =J51&K51 -> Rh.A
A52: 49 | B52: ร.ต.อ.อนุรัตน์ ศรีมาลา/ตู่ | C52: รอง สวป.สภ.ท่าแซะ ภ.จว.ชุมพร | J52: Rh. | K52: O | L52: =J52&K52 -> Rh.O
A53: 50 | B53: ร.ต.อ.ธัชพล มณีแสง/ธัช | C53: รอง สว.ศูนย์ฝึกยุทธวิธีตำรวจ บก.ฝรก. | J53: Rh. | L53: =J53&K53 -> Rh.

Sheet บัตร
G2: ปรับพื้นฐานยุทธวิธีตำรวจระดับครูฝึก(สัญญาบัตร) รุ่นที่2 | Q2: =G2 -> ปรับพื้นฐานยุทธวิธีตำรวจระดับครูฝึก(สัญญาบัตร) รุ่นที่2
G3: ประจำปีงบประมาณ 2562 | Q3: =G3 -> ประจำปีงบประมาณ 2562
G4: =ข้อมูลทำเนียบ!B4 -> พ.ต.ต.ณัฐพงษ์ กลิ่นลำยงค์/น้อย | Q4: =ข้อมูลทำเนียบ!B5 -> ร.ต.อ.สมชาติ มีความเจริญ/ชาติ
D5: 1 | N5: 1
D6: 1 | N6: 2
G9: =ข้อมูลทำเนียบ!C4 -> สวป.สน.ดินแดง บก.น.1 | Q9: =ข้อมูลทำเนียบ!C5 -> รอง สวป.สน.ห้วยขวาง บก.น.1
D10: =ข้อมูลทำเนียบ!L4 -> Rh.B | N10: =ข้อมูลทำเนียบ!L5 -> Rh.O
G15: =G2 -> ปรับพื้นฐานยุทธวิธีตำรวจระดับครูฝึก(สัญญาบัตร) รุ่นที่2 | Q15: =G2 -> ปรับพื้นฐานยุทธวิธีตำรวจระดับครูฝึก(สัญญาบัตร) รุ่นที่2
G16: =G3 -> ประจำปีงบประมาณ 2562 | Q16: =G16 -> ประจำปีงบประมาณ 2562
G17: =ข้อมูลทำเนียบ!B6 -> ร.ต.อ.สุวพิชญ์ อินทร์สิงห์/พิช | Q17: =ข้อมูลทำเนียบ!B7 -> ร.ต.อ.โสภณ คำเวียงจันทร์/ปิ๊ก
D18: 1 | N18: 1
D19: 3 | N19: 4
G22: =ข้อมูลทำเนียบ!C6 -> รอง สวป.สน.บางเขน บก.น.2 | Q22: =ข้อมูลทำเนียบ!C7 -> รอง สว.ธร.สน.โคกคราม บก.น.2
D23: =ข้อมูลทำเนียบ!L6 -> Rh.O | N23: =ข้อมูลทำเนียบ!L7 -> Rh.B
G28: =G2 -> ปรับพื้นฐานยุทธวิธีตำรวจระดับครูฝึก(สัญญาบัตร) รุ่นที่2 | Q28: =G2 -> ปรับพื้นฐานยุทธวิธีตำรวจระดับครูฝึก(สัญญาบัตร) รุ่นที่2
G29: =G16 -> ประจำปีงบประมาณ 2562 | Q29: =Q16 -> ประจำปีงบประมาณ 2562
G30: =ข้อมูลทำเนียบ!B8 -> ร.ต.อ.มณฑล แดงสมิง/แดง | Q30: =ข้อมูลทำเนียบ!B9 -> ร.ต.อ.ณภัทรพงษ์ ขันธะหัตถ์/พงษ์
D31: 1 | N31: 1
D32: 5 | N32: 6
G35: =ข้อมูลทำเนียบ!C8 -> รอง สวป.สน.มีนบุรี บก.น.3 | Q35: =ข้อมูลทำเนียบ!C9 -> รอง สวป.สน.ร่มเกล้า บก.น.3
D36: =ข้อมูลทำเนียบ!L8 -> Rh.B | N36: =ข้อมูลทำเนียบ!L9 -> Rh.B
G41: =G2 -> ปรับพื้นฐานยุทธวิธีตำรวจระดับครูฝึก(สัญญาบัตร) รุ่นที่2 | Q41: =G2 -> ปรับพื้นฐานยุทธวิธีตำรวจระดับครูฝึก(สัญญาบัตร) รุ่นที่2
G42: =G29 -> ประจำปีงบประมาณ 2562 | Q42: =Q29 -> ประจำปีงบประมาณ 2562
G43: =ข้อมูลทำเนียบ!B10 -> พ.ต.ท.ณรัฐช์พงศ์ อุดมศรี/ต้อม | Q43: =ข้อมูลทำเนียบ!B11 -> ร.ต.ท.กฤษฎา ซอประเสริฐ/จี๊
D44: 1 | N44: 1
D45: 7 | N45: 8
G49: =ข้อมูลทำเนียบ!C10 -> รอง ผกก.(ป.) สน.บึงกุ่ม บก.น.4 | Q49: =ข้อมูลทำเนียบ!C11 -> รอง สว.(สอบสวน) สน.บางชัน บก.น.4
D50: =ข้อมูลทำเนียบ!L10 -> Rh.O | N50: =ข้อมูลทำเนียบ!L11 -> Rh.A
G55: =G2 -> ปรับพื้นฐานยุทธวิธีตำรวจระดับครูฝึก(สัญญาบัตร) รุ่นที่2 | Q55: =G2 -> ปรับพื้นฐานยุทธวิธีตำรวจระดับครูฝึก(สัญญาบัตร) รุ่นที่2
G56: =G42 -> ประจำปีงบประมาณ 2562 | Q56: =Q42 -> ประจำปีงบประมาณ 2562
G57: =ข้อมูลทำเนียบ!B12 -> ร.ต.อ.สรกฤช ชุมหล่อ/พงศ์ | Q57: =ข้อมูลทำเนียบ!B13 -> ร.ต.อ.กฤษณ บัวหอม/ตุ้ม
D58: 1 | N58: 1
D59: 9 | N59: 10
G63: =ข้อมูลทำเนียบ!C12 -> รอง สวป.สน.บางนา บก.น.5 | Q63: =ข้อมูลทำเนียบ!C13 -> รอง สวป.สน.ทุ่งมหาเมฆ
D64: =ข้อมูลทำเนียบ!L12 -> Rh.O | N64: =ข้อมูลทำเนียบ!L13 -> Rh.O
G68: =G2 -> ปรับพื้นฐานยุทธวิธีตำรวจระดับครูฝึก(สัญญาบัตร) รุ่นที่2 | Q68: =G2 -> ปรับพื้นฐานยุทธวิธีตำรวจระดับครูฝึก(สัญญาบัตร) รุ่นที่2
G69: =G3 -> ประจำปีงบประมาณ 2562 | Q69: =G3 -> ประจำปีงบประมาณ 2562
G70: =ข้อมูลทำเนียบ!B14 -> ร.ต.ท.จักรพันธุ์ พันธุ์มณี /หนึ่ง | Q70: =ข้อมูลทำเนียบ!B15 -> ร.ต.อ.ดุสิต โชติสกุลแสงทอง/ดุ
D71: 1 | N71: 1
D72: 11 | N72: 12
...

Sheet ทำเนียบรุ่น
A1: หลักสูตรการปรับพื้นฐานยุทธวิธีตำรวจระดับครูฝึก (ชั้นสัญญาบัตร) รุ่นที่ 1
A2: ประจำปีงบประมาณ 2562
A3: ระหว่างวันที่ 29 กรกฎาคม - 9 สิงหาคม 2562
B5: =ข้อมูลทำเนียบ!B4 -> พ.ต.ต.ณัฐพงษ์ กลิ่นลำยงค์/น้อย | E5: =ข้อมูลทำเนียบ!D4 -> 0 | G5: 1 | I5: =ข้อมูลทำเนียบ!B5 -> ร.ต.อ.สมชาติ มีความเจริญ/ชาติ | L5: =ข้อมูลทำเนียบ!D5 -> 0 | N5: 2
B6: =ข้อมูลทำเนียบ!C4 -> สวป.สน.ดินแดง บก.น.1 | I6: =ข้อมูลทำเนียบ!C5 -> รอง สวป.สน.ห้วยขวาง บก.น.1
B7: =ข้อมูลทำเนียบ!I4 -> 0 | I7: =ข้อมูลทำเนียบ!I5 -> 0
B9: =ข้อมูลทำเนียบ!B6 -> ร.ต.อ.สุวพิชญ์ อินทร์สิงห์/พิช | E9: =ข้อมูลทำเนียบ!D6 -> 0 | G9: 3 | I9: =ข้อมูลทำเนียบ!B7 -> ร.ต.อ.โสภณ คำเวียงจันทร์/ปิ๊ก | L9: =ข้อมูลทำเนียบ!D7 -> 0 | N9: 4
B10: =ข้อมูลทำเนียบ!C6 -> รอง สวป.สน.บางเขน บก.น.2 | I10: =ข้อมูลทำเนียบ!C7 -> รอง สว.ธร.สน.โคกคราม บก.น.2
B11: =ข้อมูลทำเนียบ!I6 -> 0 | I11: =ข้อมูลทำเนียบ!I7 -> 0
B13: =ข้อมูลทำเนียบ!B8 -> ร.ต.อ.มณฑล แดงสมิง/แดง | E13: =ข้อมูลทำเนียบ!D8 -> 0 | G13: 5 | I13: =ข้อมูลทำเนียบ!B9 -> ร.ต.อ.ณภัทรพงษ์ ขันธะหัตถ์/พงษ์ | L13: =ข้อมูลทำเนียบ!D9 -> 0 | N13: 6
B14: =ข้อมูลทำเนียบ!C8 -> รอง สวป.สน.มีนบุรี บก.น.3 | I14: =ข้อมูลทำเนียบ!C9 -> รอง สวป.สน.ร่มเกล้า บก.น.3
B15: =ข้อมูลทำเนียบ!I8 -> 0 | I15: =ข้อมูลทำเนียบ!I9 -> 0
B17: =ข้อมูลทำเนียบ!B10 -> พ.ต.ท.ณรัฐช์พงศ์ อุดมศรี/ต้อม | E17: =ข้อมูลทำเนียบ!D10 -> 0 | G17: 7 | I17: =ข้อมูลทำเนียบ!B11 -> ร.ต.ท.กฤษฎา ซอประเสริฐ/จี๊ | L17: =ข้อมูลทำเนียบ!D11 -> 0 | N17: 8
B18: =ข้อมูลทำเนียบ!C10 -> รอง ผกก.(ป.) สน.บึงกุ่ม บก.น.4 | I18: =ข้อมูลทำเนียบ!C11 -> รอง สว.(สอบสวน) สน.บางชัน บก.น.4
B19: =ข้อมูลทำเนียบ!I10 -> 0 | I19: =ข้อมูลทำเนียบ!I11 -> 0
B21: =ข้อมูลทำเนียบ!B12 -> ร.ต.อ.สรกฤช ชุมหล่อ/พงศ์ | E21: =ข้อมูลทำเนียบ!D12 -> 0 | G21: 9 | I21: =ข้อมูลทำเนียบ!B13 -> ร.ต.อ.กฤษณ บัวหอม/ตุ้ม | L21: =ข้อมูลทำเนียบ!D13 -> 0 | N21: 10
B22: =ข้อมูลทำเนียบ!C12 -> รอง สวป.สน.บางนา บก.น.5 | I22: =ข้อมูลทำเนียบ!C13 -> รอง สวป.สน.ทุ่งมหาเมฆ
B23: =ข้อมูลทำเนียบ!I12 -> 0 | I23: =ข้อมูลทำเนียบ!I13 -> 0
B25: =ข้อมูลทำเนียบ!B14 -> ร.ต.ท.จักรพันธุ์ พันธุ์มณี /หนึ่ง | E25: =ข้อมูลทำเนียบ!D14 -> 0 | G25: 11 | I25: =ข้อมูลทำเนียบ!B15 -> ร.ต.อ.ดุสิต โชติสกุลแสงทอง/ดุ | L25: =ข้อมูลทำเนียบ!D15 -> 0 | N25: 12
B26: =ข้อมูลทำเนียบ!C14 -> รอง สว.กก.สืบสวน ภ.จว.จันทบุรี | I26: =ข้อมูลทำเนียบ!C15 -> รอง สวป.สภ.สอยดาว จว.ชลบุรี
B27: =ข้อมูลทำเนียบ!I14 -> 0 | I27: =ข้อมูลทำเนียบ!I15 -> 0
B29: =ข้อมูลทำเนียบ!B16 -> ร.ต.อ.ไกรศักดิ์ เฉยฉิว /ศักดิ์ | E29: =ข้อมูลทำเนียบ!D16 -> 0 | G29: 13 | I29: =ข้อมูลทำเนียบ!B17 -> ร.ต.อ.ประยงค์ อยู่สาโก /ยงค์ | L29: =ข้อมูลทำเนียบ!D17 -> 0 | N29: 14
B30: =ข้อมูลทำเนียบ!C16 -> รอง สว.จร.สภ.บางน้ำเปรี้ยว จว.ฉะเชิงเทรา | I30: =ข้อมูลทำเนียบ!C17 -> รอง สวป.สภ.แปลงยาว จว.ฉะเชิงเทรา
B31: =ข้อมูลทำเนียบ!I16 -> 0 | I31: =ข้อมูลทำเนียบ!I17 -> 0
B33: =ข้อมูลทำเนียบ!B18 -> ร.ต.อ.วุฒิพงษ์ กาสา/อู๊ด | E33: =ข้อมูลทำเนียบ!D18 -> 0 | G33: 15 | I33: =ข้อมูลทำเนียบ!B19 -> ร.ต.อ.ยงยุทธ กองทอง/ยุทธ | L33: =ข้อมูลทำเนียบ!D19 -> 0 | N33: 16
B34: =ข้อมูลทำเนียบ!C18 -> รอง สว.กก.สืบสวน ภ.จว.ชลบุรี | I34: =ข้อมูลทำเนียบ!C19 -> รอง สวป.สภ.ห้วยใหญ่ ภ.จว.ชลบุรี
B35: =ข้อมูลทำเนียบ!I18 -> 0 | I35: =ข้อมูลทำเนียบ!I19 -> 0
B38: =ข้อมูลทำเนียบ!B20 -> พ.ต.ท.อาทิตย์ ธรรมสุนา/ท๊อป | E38: =ข้อมูลทำเนียบ!D20 -> 0 | G38: 17 | I38: =ข้อมูลทำเนียบ!B21 -> ร.ต.อ.อนวัช พรมปะ /วัช | L38: =ข้อมูลทำเนียบ!D21 -> 0 | N38: 18
B39: =ข้อมูลทำเนียบ!C20 -> สวป.สภ.วังตะเคียน จว.ปราจีนบุรี | I39: =ข้อมูลทำเนียบ!C21 -> รอง สวป.สภ.ศรีมหาโพธิ จว.ปราจีนบุรี
B40: =ข้อมูลทำเนียบ!I20 -> 0 | I40: =ข้อมูลทำเนียบ!I21 -> 0
B42: =ข้อมูลทำเนียบ!B22 -> ร.ต.อ.สิทธา ช่อเกตุ /แหลม | E42: =ข้อมูลทำเนียบ!D22 -> 0 | G42: 19 | I42: =ข้อมูลทำเนียบ!B23 -> ร.ต.อ.คมเดช ศรียางนอก /ยศ | L42: =ข้อมูลทำเนียบ!D23 -> 0 | N42: 20
B43: =ข้อมูลทำเนียบ!C22 -> รอง สวป.สภ.มาบตาพุด จว.ระยอง | I43: =ข้อมูลทำเนียบ!C23 -> รอง สวป.สภ.บ้านฉาง จว.ระยอง
B44: =ข้อมูลทำเนียบ!I22 -> 0 | I44: =ข้อมูลทำเนียบ!I23 -> 0
B46: =ข้อมูลทำเนียบ!B24 -> พ.ต.ท.ชวลิต อาจหาญ/กั้ง | E46: =ข้อมูลทำเนียบ!D24 -> 0 | G46: 21 | I46: =ข้อมูลทำเนียบ!B25 -> พ.ต.ต.เนติวุธ สุดหนองบัว/เน | L46: =ข้อมูลทำเนียบ!D25 -> 0 | N46: 22
B47: =ข้อมูลทำเนียบ!C24 -> สวป.สภ.เกษตรวิสัย ภ.จว.ร้อยเอ็ด | I47: =ข้อมูลทำเนียบ!C25 -> สวป.สภ.เมืองสรวง ภ.จว.ร้อยเอ็ด
B48: =ข้อมูลทำเนียบ!I24 -> 0 | I48: =ข้อมูลทำเนียบ!I25 -> 0
B50: =ข้อมูลทำเนียบ!B26 -> ร.ต.อ.สะไกร ปิดสายะ/ไกร | E50: =ข้อมูลทำเนียบ!D26 -> 0 | G50: 23 | I50: =ข้อมูลทำเนียบ!B27 -> ร.ต.อ.ปิยพล อนันต์เอื้อ/ต๋อง | L50: =ข้อมูลทำเนียบ!D27 -> 0 | N50: 24
B51: =ข้อมูลทำเนียบ!C26 -> รอง สวป.สภ.ท่าคันโท ภ.จว.กาฬสินธุ์ | I51: =ข้อมูลทำเนียบ!C27 -> รอง สว.สส.สภ.ดอนจาน ภ.จว.กาฬสินธุ์
B52: =ข้อมูลทำเนียบ!I26 -> 0 | I52: =ข้อมูลทำเนียบ!I27 -> 0
B54: =ข้อมูลทำเนียบ!B28 -> ร.ต.อ.ศิริชัย ปลัดขวา/เม้า | E54: =ข้อมูลทำเนียบ!D28 -> 0 | G54: 25 | I54: =ข้อมูลทำเนียบ!B29 -> ร.ต.อ.สุวสันต์ นาหาร/เสือ | L54: =ข้อมูลทำเนียบ!D29 -> 0 | N54: 26
...

Sheet Sheet2
A24: 50 | B24: ร้อยตำรวจโท วรดร ใสสุชล

Sheet ห้องพัก
A1: บัญชีห้องพักผู้เข้ารับการฝึกอบรม
A2: โครงการฝึกอบรมการอยู่รอดของเจ้าหน้าที่และยุทธวิธี (O.S.T.) รุ่นที่ 1 ประจำปีงบประมาณ ๒๕61
A3: ระหว่างวันที่ 11 - 15 ธันวาคม 2560
A4: พักอาคาร AB
A5: ลำดับ | B5: ยศ ชื่อ สกุล | E5: ตำแหน่ง/สังกัด | F5: กุญแจ/ดอก | G5: มัดจำ 200 บ. | H5: หมายเลขห้อง
A6: บช.น.
